
<hr />
<p>layout: post
title:  Swift错误处理
date:   2015-03-08 22:49:49
categories: Swift
tags: Swift
—</p>

<h1 id="error-handling">错误处理（Error Handling）</h1>
<hr />

<blockquote>
  <p>2.1
翻译+校对：<a href="https://github.com/lyojo">lyojo</a> <a href="https://github.com/ray16897188">ray16897188</a> 2015-10-23
校对：<a href="http://codebuild.me">shanks</a> 2015-10-24</p>
</blockquote>

<p>本页包含内容：</p>

<ul>
  <li><a href="#representing_and_throwing_errors">表示并抛出错误</a></li>
  <li><a href="#handling_errors">处理错误</a></li>
  <li><a href="#specifying_cleanup_actions">指定清理操作</a></li>
</ul>

<p><em>错误处理（Error handling）</em>是响应错误以及从错误中恢复的过程。Swift 提供了在运行时对可恢复错误的抛出、捕获、传递和操作的一流支持。</p>

<p>某些操作无法保证总是执行完所有代码或总是生成有用的结果。可选类型可用来表示值缺失，但是当某个操作失败时，最好能得知失败的原因，从而可以作出相应的应对。</p>

<p>举个例子，假如有个从磁盘上的某个文件读取数据并进行处理的任务，该任务会有多种可能失败的情况，包括指定路径下文件并不存在，文件不具有可读权限，或者文件编码格式不兼容。区分这些不同的失败情况可以让程序解决并处理某些错误，然后把它解决不了的错误报告给用户。</p>

<blockquote>
  <p>注意<br />
Swift 中的错误处理涉及到错误处理模式，这会用到 Cocoa 和 Objective-C 中的<code>NSError</code>。关于这个类的更多信息请参见 <a href="https://developer.apple.com/library/prerelease/ios/documentation/Swift/Conceptual/BuildingCocoaApps/index.html#//apple_ref/doc/uid/TP40014216">Using Swift with Cocoa and Objective-C (Swift 2.1)</a> 中的<a href="https://developer.apple.com/library/prerelease/ios/documentation/Swift/Conceptual/BuildingCocoaApps/AdoptingCocoaDesignPatterns.html#//apple_ref/doc/uid/TP40014216-CH7-ID10">错误处理</a>。</p>
</blockquote>

<p><a name="representing_and_throwing_errors"></a>
##表示并抛出错误</p>

<p>在 Swift 中，错误用符合<code>ErrorType</code>协议的类型的值来表示。这个空协议表明该类型可以用于错误处理。</p>

<p>Swift 的枚举类型尤为适合构建一组相关的错误状态，枚举的关联值还可以提供错误状态的额外信息。例如，你可以这样表示在一个游戏中操作自动贩卖机时可能会出现的错误状态：</p>

<p><code>swift
enum VendingMachineError: ErrorType {
	case InvalidSelection				     //选择无效
	case InsufficientFunds(coinsNeeded: Int) //金额不足
	case OutOfStock			                 //缺货
}
</code></p>

<p>抛出一个错误可以让你表明有意外情况发生，导致正常的执行流程无法继续执行。抛出错误使用<code>throws</code>关键字。例如，下面的代码抛出一个错误，提示贩卖机还需要<code>5</code>个硬币：</p>

<p><code>swift
throw VendingMachineError.InsufficientFunds(coinsNeeded: 5)
</code></p>

<p><a name="handling_errors"></a>
##处理错误</p>

<p>某个错误被抛出时，附近的某部分代码必须负责处理这个错误，例如纠正这个问题、尝试另外一种方式、或是向用户报告错误。</p>

<p>Swift 中有<code>4</code>种处理错误的方式。你可以把函数抛出的错误传递给调用此函数的代码、用<code>do-catch</code>语句处理错误、将错误作为可选类型处理、或者断言此错误根本不会发生。每种方式在下面的小节中都有描述。</p>

<p>当一个函数抛出一个错误时，你的程序流程会发生改变，所以重要的是你能迅速识别代码中会抛出错误的地方。为了标识出这些地方，在调用一个能抛出错误的函数、方法或者构造器之前，加上<code>try</code>关键字，或者<code>try?</code>或<code>try!</code>这种变体。这些关键字在下面的小节中有具体讲解。</p>

<blockquote>
  <p>注意<br />
Swift 中的错误处理和其他语言中用<code>try</code>，<code>catch</code>和<code>throw</code>进行异常处理很像。和其他语言中（包括 Objective-C ）的异常处理不同的是，Swift 中的错误处理并不涉及解除调用栈，这是一个计算代价高昂的过程。就此而言，<code>throw</code>语句的性能特性是可以和<code>return</code>语句相媲美的。</p>
</blockquote>

<p><a name="propagating_errors_using_throwing_functions"></a>
### 用 throwing 函数传递错误</p>

<p>为了表示一个函数、方法或构造器可以抛出错误，在函数声明的参数列表之后加上<code>throws</code>关键字。一个标有<code>throws</code>关键字的函数被称作<em>throwing 函数</em>。如果这个函数指明了返回值类型，<code>throws</code>关键词需要写在箭头（<code>-&gt;</code>）的前面。</p>

<p><code>swift
func canThrowErrors() throws -&gt; String
func cannotThrowErrors() -&gt; String
</code></p>

<p>一个 throwing 函数可以在其内部抛出错误，并将错误传递到函数被调用时的作用域。</p>

<blockquote>
  <p>注意<br />
只有 throwing 函数可以传递错误。任何在某个非 throwing 函数内部抛出的错误只能在函数内部处理。</p>
</blockquote>

<p>下面的例子中，<code>VendingMechine</code>类有一个<code>vend(itemNamed:)</code>方法，如果请求的物品不存在、缺货或者花费超过了投入金额，该方法就会抛出一个相应的<code>VendingMachineError</code>：</p>

<p>```swift
struct Item {
	var price: Int
	var count: Int
}</p>

<p>class VendingMachine {
    var inventory = [
        “Candy Bar”: Item(price: 12, count: 7),
        “Chips”: Item(price: 10, count: 4),
        “Pretzels”: Item(price: 7, count: 11)
    ]
    var coinsDeposited = 0
    func dispenseSnack(snack: String) {
        print(“Dispensing (snack)”)
    }</p>

<pre><code>func vend(itemNamed name: String) throws {
    guard var item = inventory[name] else {
        throw VendingMachineError.InvalidSelection
    }
    
    guard item.count &gt; 0 else {
        throw VendingMachineError.OutOfStock
    }
    
    guard item.price &lt;= coinsDeposited else {
        throw VendingMachineError.InsufficientFunds(coinsNeeded: item.price - coinsDeposited)
    }
    
    coinsDeposited -= item.price
    --item.count
    inventory[name] = item
    dispenseSnack(name)
} } ```
</code></pre>

<p>在<code>vend(itemNamed:)</code>方法的实现中使用了<code>guard</code>语句来提前退出方法，确保在购买某个物品所需的条件中，有任一条件不满足时，能提前退出方法并抛出相应的错误。由于<code>throw</code>语句会立即退出方法，所以物品只有在所有条件都满足时才会被售出。</p>

<p>因为<code>vend(itemNamed:)</code>方法会传递出它抛出的任何错误，在你的代码中调用此方法的地方，必须要么直接处理这些错误——使用<code>do-catch</code>语句，<code>try?</code>或<code>try!</code>；要么继续将这些错误传递下去。例如下面例子中，<code>buyFavoriteSnack(_:vendingMachine:)</code>同样是一个 throwing 函数，任何由<code>vend(itemNamed:)</code>方法抛出的错误会一直被传递到<code>buyFavoriteSnack(_:vendingMachine:)</code>函数被调用的地方。</p>

<p><code>swift
let favoriteSnacks = [
	"Alice": "Chips",
	"Bob": "Licorice",
	"Eve": "Pretzels",
]
func buyFavoriteSnack(person: String, vendingMachine: VendingMachine) throws {
	let snackName = favoriteSnacks[person] ?? "Candy Bar"
	try vendingMachine.vend(itemNamed: snackName)
}
</code></p>

<p>上例中，<code>buyFavoriteSnack(_:vendingMachine:)</code>函数会查找某人最喜欢的零食，并通过调用<code>vend(itemNamed:)</code>方法来尝试为他们购买。因为<code>vend(itemNamed:)</code>方法能抛出错误，所以在调用的它时候在它前面加了<code>try</code>关键字。</p>

<h3 id="do-catch-">用 Do-Catch 处理错误</h3>

<p>可以使用一个<code>do-catch</code>语句运行一段闭包代码来处理错误。如果在<code>do</code>子句中的代码抛出了一个错误，这个错误会与<code>catch</code>子句做匹配，从而决定哪条子句能处理它。</p>

<p>下面是<code>do-catch</code>语句的一般形式：</p>

<p><code>swift
do {
    try expression
    statements
} catch pattern 1 {
    statements
} catch pattern 2 where condition {
    statements
}
</code></p>

<p>在<code>catch</code>后面写一个匹配模式来表明这个子句能处理什么样的错误。如果一条<code>catch</code>子句没有指定匹配模式，那么这条子句可以匹配任何错误，并且把错误绑定到一个名字为<code>error</code>的局部常量。关于模式匹配的更多信息请参考 <a href="../chapter3/07_Patterns.html">模式</a>。</p>

<p><code>catch</code>子句不必将<code>do</code>子句中的代码所抛出的每一个可能的错误都作处理。如果所有<code>catch</code>子句都未处理错误，错误就会传递到周围的作用域。然而，错误还是必须要被某个周围的作用域处理的——要么是一个外围的<code>do-catch</code>错误处理语句，要么是一个 throwing 函数的内部。举例来说，下面的代码处理了<code>VendingMachineError</code>枚举类型的全部枚举值，但是所有其它的错误就必须由它周围的作用域处理：</p>

<p><code>swift
var vendingMachine = VendingMachine()
vendingMachine.coinsDeposited = 8
do {
    try buyFavoriteSnack("Alice", vendingMachine: vendingMachine)
} catch VendingMachineError.InvalidSelection {
    print("Invalid Selection.")
} catch VendingMachineError.OutOfStock {
    print("Out of Stock.")
} catch VendingMachineError.InsufficientFunds(let coinsNeeded) {
    print("Insufficient funds. Please insert an additional \(coinsNeeded) coins.")
}
// 打印 “Insufficient funds. Please insert an additional 2 coins.”
</code></p>

<p>上面的例子中，<code>buyFavoriteSnack(_:vendingMachine:)</code>函数在一个<code>try</code>表达式中调用，因为它能抛出错误。如果错误被抛出，相应的执行会马上转移到<code>catch</code>子句中，并判断这个错误是否要被继续传递下去。如果没有错误抛出，<code>do</code>子句中余下的语句就会被执行。</p>

<h3 id="section">将错误转换成可选值</h3>

<p>可以使用<code>try?</code>通过将错误转换成一个可选值来处理错误。如果在评估<code>try?</code>表达式时一个错误被抛出，那么表达式的值就是<code>nil</code>。例如下面代码中的<code>x</code>和<code>y</code>具有相同的值：</p>

<p>```swift
func someThrowingFunction() throws -&gt; Int {
    // …
}</p>

<p>let x = try? someThrowingFunction()</p>

<p>let y: Int?
do {
    y = try someThrowingFunction()
} catch {
    y = nil
}
```</p>

<p>如果<code>someThrowingFunction()</code>抛出一个错误，<code>x</code>和<code>y</code>的值是<code>nil</code>。否则<code>x</code>和<code>y</code>的值就是该函数的返回值。注意，无论<code>someThrowingFunction()</code>的返回值类型是什么类型，<code>x</code>和<code>y</code>都是这个类型的可选类型。例子中此函数返回一个整型，所以<code>x</code>和<code>y</code>是可选整型。</p>

<p>如果你想对所有的错误都采用同样的方式来处理，用<code>try?</code>就可以让你写出简洁的错误处理代码。例如，下面的代码用几种方式来获取数据，如果所有方式都失败了则返回<code>nil</code>：</p>

<p><code>swift
func fetchData() -&gt; Data? {
    if let data = try? fetchDataFromDisk() { return data }
    if let data = try? fetchDataFromServer() { return data }
    return nil
}
</code></p>

<h3 id="section-1">禁用错误传递</h3>

<p>有时你知道某个 throwing 函数实际上在运行时是不会抛出错误的，在这种情况下，你可以在表达式前面写<code>try!</code>来禁用错误传递，这会把调用包装在一个断言不会有错误抛出的运行时断言中。如果实际上抛出了错误，你会得到一个运行时错误。</p>

<p>例如，下面的代码使用了<code>loadImage(_:)</code>函数，该函数从给定的路径加载图片资源，如果图片无法载入则抛出一个错误。在这种情况下，因为图片是和应用绑定的，运行时不会有错误抛出，所以适合禁用错误传递：</p>

<p><code>swift
let photo = try! loadImage("./Resources/John Appleseed.jpg")
</code></p>

<p><a name="specifying_cleanup_actions"></a>
##指定清理操作</p>

<p>可以使用<code>defer</code>语句在即将离开当前代码块时执行一系列语句。该语句让你能执行一些必要的清理工作，不管是以何种方式离开当前代码块的——无论是由于抛出错误而离开，还是由于诸如<code>return</code>或者<code>break</code>的语句。例如，你可以用<code>defer</code>语句来确保文件描述符得以关闭，以及手动分配的内存得以释放。</p>

<p><code>defer</code>语句将代码的执行延迟到当前的作用域退出之前。该语句由<code>defer</code>关键字和要被延迟执行的语句组成。延迟执行的语句不能包含任何控制转移语句，例如<code>break</code>或是<code>return</code>语句，或是抛出一个错误。延迟执行的操作会按照它们被指定时的顺序的相反顺序执行——也就是说，第一条<code>defer</code>语句中的代码会在第二条<code>defer</code>语句中的代码被执行之后才执行，以此类推。</p>

<p><code>swift
func processFile(filename: String) throws {
    if exists(filename) {
        let file = open(filename)
        defer {
            close(file)
        }
        while let line = try file.readline() {
            // 处理文件。
        }
        // close(file) 会在这里被调用，即作用域的最后。
    }
}
</code></p>

<p>上面的代码使用一条<code>defer</code>语句来确保<code>open(_:)</code>函数有一个相应的对<code>close(_:)</code>函数的调用。</p>

<blockquote>
  <p>注意<br />
即使没有涉及到错误处理，你也可以使用<code>defer</code>语句。</p>
</blockquote>
